Workbook

Sheet HOME
B1: =Settings!$B$4 -> Gulf Star Manpower Services LLC
B2: ="Manpower Management System | Payroll month: "&TEXT(Settings!$B$8,"mmmm yyyy") -> Manpower Management System | Payroll month: October 2026
B4: Client Billing (AED) | F4: Gross Profit (AED) | J4: Net Salary to Pay - WPS (AED)
B5: =Dashboard!$B$4 -> 324858.76 | F5: =Dashboard!$B$7 -> 136300.32 | J5: =Dashboard!$B$15 -> 87430.82
B6: =IF(Dashboard!$B$18+Dashboard!$B$19=0,"All visas / Emirates IDs OK","WARNING: "&Dashboard!$B$18&" documents EXPIRED, "&Dashboard!$B$19&" expiring soon - open Workers") -> WARNING: 6 documents EXPIRED, 12 expiring soon - open Workers
B8: 1. ENTER DATA
B9: Timesheet | F9: Deductions | J9: Workers
B11: Client hours each month | F11: Advances, fines | J11: Add / edit workers
B13: 2. MASTER DATA
B14: Clients | F14: Suppliers | J14: Client Rates
B16: Customers | F16: Manpower agencies | J16: Selling rate / hr
B18: Supplier Rates | F18: Settings | J18: Help
B20: Cost rate / hr | F20: Month, OT, VAT | J20: How it works
B22: 3. REPORTS & PRINT
B23: Dashboard | F23: Payroll | J23: Payslip
B25: Profit & KPIs | F25: Salary sheet | J25: Print payslip
B27: Client Invoice | F27: Supplier Payment | J27: WPS File
B29: Tax invoice | F29: Amount payable | J29: Bank salary file
B31: Click any tile to open. Every sheet has a « HOME link at the top right to come back.

Sheet README
A1: Manpower Management System - Excel Demo | C1: « HOME
A2: Own workers + supplier workers -> clients -> timesheet -> payroll, supplier payment, client invoice
A4: HOW THE FLOW WORKS
A5: 1. Settings | B5: Choose the payroll month and company rules (OT rate, VAT, working days).
A6: 2. Clients / Suppliers | B6: Master list of customers and manpower suppliers (one row each).
A7: 3. ClientRates | B7: What you CHARGE each client per hour, per trade (normal + OT).
A8: 4. SupplierRates | B8: What each supplier CHARGES YOU per hour, per trade (normal + OT).
A9: 5. Workers | B9: Every worker: Source = Own or Supplier. Own workers have salary, IBAN, labour card.
A10: 6. Timesheet | B10: Monthly hours received from the client. ONLY enter columns A-H; the rest is calculated.
A11: 7. Deductions | B11: Salary advances, fines, accommodation etc. for own workers.
A13: AUTOMATIC OUTPUT SHEETS
A14: Dashboard | B14: Month KPIs: billing, supplier cost, own payroll, profit, profit per client, document alerts.
A15: Payroll | B15: Own workers' salary for the month (fixed, hourly, OT, deductions, net pay).
A16: Payslip | B16: Pick a Worker ID in cell C4 -> printable payslip.
A17: ClientInvoice | B17: Pick a Client ID in cell C4 -> tax invoice with trade-wise hours and 5% VAT.
A18: SupplierStatement | B18: How much to pay each supplier this month, incl. VAT and due date.
A19: WPS_SIF | B19: Salary rows in WPS SIF layout (EDR + SCR). Confirm exact format with your bank/exchange.
A21: COLOUR LEGEND
A22: Blue text / yellow cell | B22: Input - type here.
A23: Black text | B23: Formula - do not overwrite.
A24: Dark blue header | B24: Input column. Light blue header = calculated column.
A25: Red row | B25: Visa / Emirates ID expired or expiring within the alert days (Settings).
A27: MONTHLY ROUTINE
A28: Step 1 | B28: Settings!B8 -> set the month (1st day of month).
A29: Step 2 | B29: Paste/enter client timesheets in Timesheet (Month, Client, Site, Worker ID, Days, Hours, OT).
A30: Step 3 | B30: Enter advances / fines in Deductions.
A31: Step 4 | B31: Check Dashboard -> print Payslips, ClientInvoice, SupplierStatement, export WPS_SIF.
A33: ASSUMPTIONS (change in Settings)
A34: Monthly salary | B34: Absent days = Standard working days - Days worked; deduction = (Basic+Allowances)/30 x absent days.
A35: Overtime | B35: UAE practice: OT hourly = Basic/30/8 x 1.25 (multiplier editable). Hourly workers: rate x 1.25.
A36: Own worker cost per hour | B36: Used for profit per client = (Basic+Allowances)/(Std days x hours per day).
A37: Sample data | B37: All names, companies, IDs and rates are fictional examples.

Sheet Dashboard
A1: Dashboard | D1: « HOME
A2: ="Month: "&TEXT(Settings!$B$8,"mmmm yyyy") -> Month: October 2026 | D2: Profit by Client (this month)
A3: (change month in Settings!B8) | D3: Client ID | E3: Client Name | F3: Lines | G3: Billing (AED) | H3: Supplier Cost | I3: Own Cost Est. | J3: Profit (AED) | K3: Margin %
A4: Client Billing (excl. VAT) | B4: =SUMIFS(Timesheet!$O$5:$O$3004,Timesheet!$A$5:$A$3004,">="&Settings!$B$8,Timesheet!$A$5:$A$3004,"<="&Settings!$B$9) -> 324858.76 | D4: =IF(Clients!A5="","",Clients!A5) -> C001 | E4: =IF($D4="","",Clients!B5) -> Al Waha Contracting LLC | F4: =IF($D4="","",COUNTIFS(Timesheet!$B$5:$B$3004,$D4,Timesheet!$A$5:$A$3004,">="&Settings!$B$8,Timesheet!$A$5:$A$3004,"<="&Settings!$B$9)) -> 23 | G4: =IF($D4="","",SUMIFS(Timesheet!$O$5:$O$3004,Timesheet!$B$5:$B$3004,$D4,Timesheet!$A$5:$A$3004,">="&Settings!$B$8,Timesheet!$A$5:$A$3004,"<="&Settings!$B$9)) -> 97921 | H4: =IF($D4="","",SUMIFS(Timesheet!$R$5:$R$3004,Timesheet!$B$5:$B$3004,$D4,Timesheet!$A$5:$A$3004,">="&Settings!$B$8,Timesheet!$A$5:$A$3004,"<="&Settings!$B$9)) -> 31153.9 | I4: =IF($D4="","",SUMIFS(Timesheet!$S$5:$S$3004,Timesheet!$B$5:$B$3004,$D4,Timesheet!$A$5:$A$3004,">="&Settings!$B$8,Timesheet!$A$5:$A$3004,"<="&Settings!$B$9)) -> 26384.087 | J4: =IF($D4="","",G4-H4-I4) -> 40383.013 | K4: =IF(OR($D4="",N(G4)=0),"",J4/G4) -> 0.41240401
A5: Supplier Cost (excl. VAT) | B5: =SUMIFS(Timesheet!$R$5:$R$3004,Timesheet!$A$5:$A$3004,">="&Settings!$B$8,Timesheet!$A$5:$A$3004,"<="&Settings!$B$9) -> 99352.62 | D5: =IF(Clients!A6="","",Clients!A6) -> C002 | E5: =IF($D5="","",Clients!B6) -> Blue Creek Facilities Mgmt | F5: =IF($D5="","",COUNTIFS(Timesheet!$B$5:$B$3004,$D5,Timesheet!$A$5:$A$3004,">="&Settings!$B$8,Timesheet!$A$5:$A$3004,"<="&Settings!$B$9)) -> 19 | G5: =IF($D5="","",SUMIFS(Timesheet!$O$5:$O$3004,Timesheet!$B$5:$B$3004,$D5,Timesheet!$A$5:$A$3004,">="&Settings!$B$8,Timesheet!$A$5:$A$3004,"<="&Settings!$B$9)) -> 95547.14 | H5: =IF($D5="","",SUMIFS(Timesheet!$R$5:$R$3004,Timesheet!$B$5:$B$3004,$D5,Timesheet!$A$5:$A$3004,">="&Settings!$B$8,Timesheet!$A$5:$A$3004,"<="&Settings!$B$9)) -> 24791.58 | I5: =IF($D5="","",SUMIFS(Timesheet!$S$5:$S$3004,Timesheet!$B$5:$B$3004,$D5,Timesheet!$A$5:$A$3004,">="&Settings!$B$8,Timesheet!$A$5:$A$3004,"<="&Settings!$B$9)) -> 26544.837 | J5: =IF($D5="","",G5-H5-I5) -> 44210.723 | K5: =IF(OR($D5="",N(G5)=0),"",J5/G5) -> 0.46271111
A6: Own Workers Payroll (Gross) | B6: =Payroll!$N$3 -> 89205.82 | D6: =IF(Clients!A7="","",Clients!A7) -> C003 | E6: =IF($D6="","",Clients!B7) -> Sandline Construction Co. | F6: =IF($D6="","",COUNTIFS(Timesheet!$B$5:$B$3004,$D6,Timesheet!$A$5:$A$3004,">="&Settings!$B$8,Timesheet!$A$5:$A$3004,"<="&Settings!$B$9)) -> 19 | G6: =IF($D6="","",SUMIFS(Timesheet!$O$5:$O$3004,Timesheet!$B$5:$B$3004,$D6,Timesheet!$A$5:$A$3004,">="&Settings!$B$8,Timesheet!$A$5:$A$3004,"<="&Settings!$B$9)) -> 73433.96 | H6: =IF($D6="","",SUMIFS(Timesheet!$R$5:$R$3004,Timesheet!$B$5:$B$3004,$D6,Timesheet!$A$5:$A$3004,">="&Settings!$B$8,Timesheet!$A$5:$A$3004,"<="&Settings!$B$9)) -> 23265.76 | I6: =IF($D6="","",SUMIFS(Timesheet!$S$5:$S$3004,Timesheet!$B$5:$B$3004,$D6,Timesheet!$A$5:$A$3004,">="&Settings!$B$8,Timesheet!$A$5:$A$3004,"<="&Settings!$B$9)) -> 23818.75 | J6: =IF($D6="","",G6-H6-I6) -> 26349.45 | K6: =IF(OR($D6="",N(G6)=0),"",J6/G6) -> 0.35881832
A7: GROSS PROFIT | B7: =B4-B5-B6 -> 136300.32 | D7: =IF(Clients!A8="","",Clients!A8) -> C004 | E7: =IF($D7="","",Clients!B8) -> Marina Hospitality Group | F7: =IF($D7="","",COUNTIFS(Timesheet!$B$5:$B$3004,$D7,Timesheet!$A$5:$A$3004,">="&Settings!$B$8,Timesheet!$A$5:$A$3004,"<="&Settings!$B$9)) -> 13 | G7: =IF($D7="","",SUMIFS(Timesheet!$O$5:$O$3004,Timesheet!$B$5:$B$3004,$D7,Timesheet!$A$5:$A$3004,">="&Settings!$B$8,Timesheet!$A$5:$A$3004,"<="&Settings!$B$9)) -> 57956.66 | H7: =IF($D7="","",SUMIFS(Timesheet!$R$5:$R$3004,Timesheet!$B$5:$B$3004,$D7,Timesheet!$A$5:$A$3004,">="&Settings!$B$8,Timesheet!$A$5:$A$3004,"<="&Settings!$B$9)) -> 20141.38 | I7: =IF($D7="","",SUMIFS(Timesheet!$S$5:$S$3004,Timesheet!$B$5:$B$3004,$D7,Timesheet!$A$5:$A$3004,">="&Settings!$B$8,Timesheet!$A$5:$A$3004,"<="&Settings!$B$9)) -> 14190.154 | J7: =IF($D7="","",G7-H7-I7) -> 23625.126 | K7: =IF(OR($D7="",N(G7)=0),"",J7/G7) -> 0.40763436
A8: Gross Margin % | B8: =IF(B4=0,0,B7/B4) -> 0.41956794 | D8: =IF(Clients!A9="","",Clients!A9) | E8: =IF($D8="","",Clients!B9) | F8: =IF($D8="","",COUNTIFS(Timesheet!$B$5:$B$3004,$D8,Timesheet!$A$5:$A$3004,">="&Settings!$B$8,Timesheet!$A$5:$A$3004,"<="&Settings!$B$9)) | G8: =IF($D8="","",SUMIFS(Timesheet!$O$5:$O$3004,Timesheet!$B$5:$B$3004,$D8,Timesheet!$A$5:$A$3004,">="&Settings!$B$8,Timesheet!$A$5:$A$3004,"<="&Settings!$B$9)) | H8: =IF($D8="","",SUMIFS(Timesheet!$R$5:$R$3004,Timesheet!$B$5:$B$3004,$D8,Timesheet!$A$5:$A$3004,">="&Settings!$B$8,Timesheet!$A$5:$A$3004,"<="&Settings!$B$9)) | I8: =IF($D8="","",SUMIFS(Timesheet!$S$5:$S$3004,Timesheet!$B$5:$B$3004,$D8,Timesheet!$A$5:$A$3004,">="&Settings!$B$8,Timesheet!$A$5:$A$3004,"<="&Settings!$B$9)) | J8: =IF($D8="","",G8-H8-I8) | K8: =IF(OR($D8="",N(G8)=0),"",J8/G8)
A9: VAT Output (on billing) | B9: =ROUND(B4*Settings!$B$14,2) -> 16242.94 | D9: =IF(Clients!A10="","",Clients!A10) | E9: =IF($D9="","",Clients!B10) | F9: =IF($D9="","",COUNTIFS(Timesheet!$B$5:$B$3004,$D9,Timesheet!$A$5:$A$3004,">="&Settings!$B$8,Timesheet!$A$5:$A$3004,"<="&Settings!$B$9)) | G9: =IF($D9="","",SUMIFS(Timesheet!$O$5:$O$3004,Timesheet!$B$5:$B$3004,$D9,Timesheet!$A$5:$A$3004,">="&Settings!$B$8,Timesheet!$A$5:$A$3004,"<="&Settings!$B$9)) | H9: =IF($D9="","",SUMIFS(Timesheet!$R$5:$R$3004,Timesheet!$B$5:$B$3004,$D9,Timesheet!$A$5:$A$3004,">="&Settings!$B$8,Timesheet!$A$5:$A$3004,"<="&Settings!$B$9)) | I9: =IF($D9="","",SUMIFS(Timesheet!$S$5:$S$3004,Timesheet!$B$5:$B$3004,$D9,Timesheet!$A$5:$A$3004,">="&Settings!$B$8,Timesheet!$A$5:$A$3004,"<="&Settings!$B$9)) | J9: =IF($D9="","",G9-H9-I9) | K9: =IF(OR($D9="",N(G9)=0),"",J9/G9)
D10: =IF(Clients!A11="","",Clients!A11) | E10: =IF($D10="","",Clients!B11) | F10: =IF($D10="","",COUNTIFS(Timesheet!$B$5:$B$3004,$D10,Timesheet!$A$5:$A$3004,">="&Settings!$B$8,Timesheet!$A$5:$A$3004,"<="&Settings!$B$9)) | G10: =IF($D10="","",SUMIFS(Timesheet!$O$5:$O$3004,Timesheet!$B$5:$B$3004,$D10,Timesheet!$A$5:$A$3004,">="&Settings!$B$8,Timesheet!$A$5:$A$3004,"<="&Settings!$B$9)) | H10: =IF($D10="","",SUMIFS(Timesheet!$R$5:$R$3004,Timesheet!$B$5:$B$3004,$D10,Timesheet!$A$5:$A$3004,">="&Settings!$B$8,Timesheet!$A$5:$A$3004,"<="&Settings!$B$9)) | I10: =IF($D10="","",SUMIFS(Timesheet!$S$5:$S$3004,Timesheet!$B$5:$B$3004,$D10,Timesheet!$A$5:$A$3004,">="&Settings!$B$8,Timesheet!$A$5:$A$3004,"<="&Settings!$B$9)) | J10: =IF($D10="","",G10-H10-I10) | K10: =IF(OR($D10="",N(G10)=0),"",J10/G10)
A11: Total Billable Hours | B11: =SUMIFS(Timesheet!$F$5:$F$3004,Timesheet!$A$5:$A$3004,">="&Settings!$B$8,Timesheet!$A$5:$A$3004,"<="&Settings!$B$9)+SUMIFS(Timesheet!$G$5:$G$3004,Timesheet!$A$5:$A$3004,">="&Settings!$B$8,Timesheet!$A$5:$A$3004,"<="&Settings!$B$9) -> 14600 | D11: =IF(Clients!A12="","",Clients!A12) | E11: =IF($D11="","",Clients!B12) | F11: =IF($D11="","",COUNTIFS(Timesheet!$B$5:$B$3004,$D11,Timesheet!$A$5:$A$3004,">="&Settings!$B$8,Timesheet!$A$5:$A$3004,"<="&Settings!$B$9)) | G11: =IF($D11="","",SUMIFS(Timesheet!$O$5:$O$3004,Timesheet!$B$5:$B$3004,$D11,Timesheet!$A$5:$A$3004,">="&Settings!$B$8,Timesheet!$A$5:$A$3004,"<="&Settings!$B$9)) | H11: =IF($D11="","",SUMIFS(Timesheet!$R$5:$R$3004,Timesheet!$B$5:$B$3004,$D11,Timesheet!$A$5:$A$3004,">="&Settings!$B$8,Timesheet!$A$5:$A$3004,"<="&Settings!$B$9)) | I11: =IF($D11="","",SUMIFS(Timesheet!$S$5:$S$3004,Timesheet!$B$5:$B$3004,$D11,Timesheet!$A$5:$A$3004,">="&Settings!$B$8,Timesheet!$A$5:$A$3004,"<="&Settings!$B$9)) | J11: =IF($D11="","",G11-H11-I11) | K11: =IF(OR($D11="",N(G11)=0),"",J11/G11)
A12: Timesheet Lines (this month) | B12: =COUNTIFS(Timesheet!$A$5:$A$3004,">="&Settings!$B$8,Timesheet!$A$5:$A$3004,"<="&Settings!$B$9) -> 74 | D12: =IF(Clients!A13="","",Clients!A13) | E12: =IF($D12="","",Clients!B13) | F12: =IF($D12="","",COUNTIFS(Timesheet!$B$5:$B$3004,$D12,Timesheet!$A$5:$A$3004,">="&Settings!$B$8,Timesheet!$A$5:$A$3004,"<="&Settings!$B$9)) | G12: =IF($D12="","",SUMIFS(Timesheet!$O$5:$O$3004,Timesheet!$B$5:$B$3004,$D12,Timesheet!$A$5:$A$3004,">="&Settings!$B$8,Timesheet!$A$5:$A$3004,"<="&Settings!$B$9)) | H12: =IF($D12="","",SUMIFS(Timesheet!$R$5:$R$3004,Timesheet!$B$5:$B$3004,$D12,Timesheet!$A$5:$A$3004,">="&Settings!$B$8,Timesheet!$A$5:$A$3004,"<="&Settings!$B$9)) | I12: =IF($D12="","",SUMIFS(Timesheet!$S$5:$S$3004,Timesheet!$B$5:$B$3004,$D12,Timesheet!$A$5:$A$3004,">="&Settings!$B$8,Timesheet!$A$5:$A$3004,"<="&Settings!$B$9)) | J12: =IF($D12="","",G12-H12-I12) | K12: =IF(OR($D12="",N(G12)=0),"",J12/G12)
A13: Active Own Workers | B13: =COUNTIFS(Workers!$C$5:$C$2004,"Own",Workers!$Q$5:$Q$2004,"Active") -> 40 | D13: =IF(Clients!A14="","",Clients!A14) | E13: =IF($D13="","",Clients!B14) | F13: =IF($D13="","",COUNTIFS(Timesheet!$B$5:$B$3004,$D13,Timesheet!$A$5:$A$3004,">="&Settings!$B$8,Timesheet!$A$5:$A$3004,"<="&Settings!$B$9)) | G13: =IF($D13="","",SUMIFS(Timesheet!$O$5:$O$3004,Timesheet!$B$5:$B$3004,$D13,Timesheet!$A$5:$A$3004,">="&Settings!$B$8,Timesheet!$A$5:$A$3004,"<="&Settings!$B$9)) | H13: =IF($D13="","",SUMIFS(Timesheet!$R$5:$R$3004,Timesheet!$B$5:$B$3004,$D13,Timesheet!$A$5:$A$3004,">="&Settings!$B$8,Timesheet!$A$5:$A$3004,"<="&Settings!$B$9)) | I13: =IF($D13="","",SUMIFS(Timesheet!$S$5:$S$3004,Timesheet!$B$5:$B$3004,$D13,Timesheet!$A$5:$A$3004,">="&Settings!$B$8,Timesheet!$A$5:$A$3004,"<="&Settings!$B$9)) | J13: =IF($D13="","",G13-H13-I13) | K13: =IF(OR($D13="",N(G13)=0),"",J13/G13)
A14: Active Supplier Workers | B14: =COUNTIFS(Workers!$C$5:$C$2004,"Supplier",Workers!$Q$5:$Q$2004,"Active") -> 30 | D14: =IF(Clients!A15="","",Clients!A15) | E14: =IF($D14="","",Clients!B15) | F14: =IF($D14="","",COUNTIFS(Timesheet!$B$5:$B$3004,$D14,Timesheet!$A$5:$A$3004,">="&Settings!$B$8,Timesheet!$A$5:$A$3004,"<="&Settings!$B$9)) | G14: =IF($D14="","",SUMIFS(Timesheet!$O$5:$O$3004,Timesheet!$B$5:$B$3004,$D14,Timesheet!$A$5:$A$3004,">="&Settings!$B$8,Timesheet!$A$5:$A$3004,"<="&Settings!$B$9)) | H14: =IF($D14="","",SUMIFS(Timesheet!$R$5:$R$3004,Timesheet!$B$5:$B$3004,$D14,Timesheet!$A$5:$A$3004,">="&Settings!$B$8,Timesheet!$A$5:$A$3004,"<="&Settings!$B$9)) | I14: =IF($D14="","",SUMIFS(Timesheet!$S$5:$S$3004,Timesheet!$B$5:$B$3004,$D14,Timesheet!$A$5:$A$3004,">="&Settings!$B$8,Timesheet!$A$5:$A$3004,"<="&Settings!$B$9)) | J14: =IF($D14="","",G14-H14-I14) | K14: =IF(OR($D14="",N(G14)=0),"",J14/G14)
A15: Net Salary to Pay (WPS) | B15: =Payroll!$R$3 -> 87430.82 | D15: =IF(Clients!A16="","",Clients!A16) | E15: =IF($D15="","",Clients!B16) | F15: =IF($D15="","",COUNTIFS(Timesheet!$B$5:$B$3004,$D15,Timesheet!$A$5:$A$3004,">="&Settings!$B$8,Timesheet!$A$5:$A$3004,"<="&Settings!$B$9)) | G15: =IF($D15="","",SUMIFS(Timesheet!$O$5:$O$3004,Timesheet!$B$5:$B$3004,$D15,Timesheet!$A$5:$A$3004,">="&Settings!$B$8,Timesheet!$A$5:$A$3004,"<="&Settings!$B$9)) | H15: =IF($D15="","",SUMIFS(Timesheet!$R$5:$R$3004,Timesheet!$B$5:$B$3004,$D15,Timesheet!$A$5:$A$3004,">="&Settings!$B$8,Timesheet!$A$5:$A$3004,"<="&Settings!$B$9)) | I15: =IF($D15="","",SUMIFS(Timesheet!$S$5:$S$3004,Timesheet!$B$5:$B$3004,$D15,Timesheet!$A$5:$A$3004,">="&Settings!$B$8,Timesheet!$A$5:$A$3004,"<="&Settings!$B$9)) | J15: =IF($D15="","",G15-H15-I15) | K15: =IF(OR($D15="",N(G15)=0),"",J15/G15)
A16: Payable to Suppliers (incl. VAT) | B16: =SupplierStatement!$I$3 -> 104320.25 | D16: =IF(Clients!A17="","",Clients!A17) | E16: =IF($D16="","",Clients!B17) | F16: =IF($D16="","",COUNTIFS(Timesheet!$B$5:$B$3004,$D16,Timesheet!$A$5:$A$3004,">="&Settings!$B$8,Timesheet!$A$5:$A$3004,"<="&Settings!$B$9)) | G16: =IF($D16="","",SUMIFS(Timesheet!$O$5:$O$3004,Timesheet!$B$5:$B$3004,$D16,Timesheet!$A$5:$A$3004,">="&Settings!$B$8,Timesheet!$A$5:$A$3004,"<="&Settings!$B$9)) | H16: =IF($D16="","",SUMIFS(Timesheet!$R$5:$R$3004,Timesheet!$B$5:$B$3004,$D16,Timesheet!$A$5:$A$3004,">="&Settings!$B$8,Timesheet!$A$5:$A$3004,"<="&Settings!$B$9)) | I16: =IF($D16="","",SUMIFS(Timesheet!$S$5:$S$3004,Timesheet!$B$5:$B$3004,$D16,Timesheet!$A$5:$A$3004,">="&Settings!$B$8,Timesheet!$A$5:$A$3004,"<="&Settings!$B$9)) | J16: =IF($D16="","",G16-H16-I16) | K16: =IF(OR($D16="",N(G16)=0),"",J16/G16)
D17: =IF(Clients!A18="","",Clients!A18) | E17: =IF($D17="","",Clients!B18) | F17: =IF($D17="","",COUNTIFS(Timesheet!$B$5:$B$3004,$D17,Timesheet!$A$5:$A$3004,">="&Settings!$B$8,Timesheet!$A$5:$A$3004,"<="&Settings!$B$9)) | G17: =IF($D17="","",SUMIFS(Timesheet!$O$5:$O$3004,Timesheet!$B$5:$B$3004,$D17,Timesheet!$A$5:$A$3004,">="&Settings!$B$8,Timesheet!$A$5:$A$3004,"<="&Settings!$B$9)) | H17: =IF($D17="","",SUMIFS(Timesheet!$R$5:$R$3004,Timesheet!$B$5:$B$3004,$D17,Timesheet!$A$5:$A$3004,">="&Settings!$B$8,Timesheet!$A$5:$A$3004,"<="&Settings!$B$9)) | I17: =IF($D17="","",SUMIFS(Timesheet!$S$5:$S$3004,Timesheet!$B$5:$B$3004,$D17,Timesheet!$A$5:$A$3004,">="&Settings!$B$8,Timesheet!$A$5:$A$3004,"<="&Settings!$B$9)) | J17: =IF($D17="","",G17-H17-I17) | K17: =IF(OR($D17="",N(G17)=0),"",J17/G17)
A18: Documents EXPIRED | B18: =COUNTIF(Workers!$T$5:$T$2004,"EXPIRED") -> 6 | D18: =IF(Clients!A19="","",Clients!A19) | E18: =IF($D18="","",Clients!B19) | F18: =IF($D18="","",COUNTIFS(Timesheet!$B$5:$B$3004,$D18,Timesheet!$A$5:$A$3004,">="&Settings!$B$8,Timesheet!$A$5:$A$3004,"<="&Settings!$B$9)) | G18: =IF($D18="","",SUMIFS(Timesheet!$O$5:$O$3004,Timesheet!$B$5:$B$3004,$D18,Timesheet!$A$5:$A$3004,">="&Settings!$B$8,Timesheet!$A$5:$A$3004,"<="&Settings!$B$9)) | H18: =IF($D18="","",SUMIFS(Timesheet!$R$5:$R$3004,Timesheet!$B$5:$B$3004,$D18,Timesheet!$A$5:$A$3004,">="&Settings!$B$8,Timesheet!$A$5:$A$3004,"<="&Settings!$B$9)) | I18: =IF($D18="","",SUMIFS(Timesheet!$S$5:$S$3004,Timesheet!$B$5:$B$3004,$D18,Timesheet!$A$5:$A$3004,">="&Settings!$B$8,Timesheet!$A$5:$A$3004,"<="&Settings!$B$9)) | J18: =IF($D18="","",G18-H18-I18) | K18: =IF(OR($D18="",N(G18)=0),"",J18/G18)
A19: Documents EXPIRING SOON | B19: =COUNTIF(Workers!$T$5:$T$2004,"EXPIRING SOON") -> 12 | D19: =IF(Clients!A20="","",Clients!A20) | E19: =IF($D19="","",Clients!B20) | F19: =IF($D19="","",COUNTIFS(Timesheet!$B$5:$B$3004,$D19,Timesheet!$A$5:$A$3004,">="&Settings!$B$8,Timesheet!$A$5:$A$3004,"<="&Settings!$B$9)) | G19: =IF($D19="","",SUMIFS(Timesheet!$O$5:$O$3004,Timesheet!$B$5:$B$3004,$D19,Timesheet!$A$5:$A$3004,">="&Settings!$B$8,Timesheet!$A$5:$A$3004,"<="&Settings!$B$9)) | H19: =IF($D19="","",SUMIFS(Timesheet!$R$5:$R$3004,Timesheet!$B$5:$B$3004,$D19,Timesheet!$A$5:$A$3004,">="&Settings!$B$8,Timesheet!$A$5:$A$3004,"<="&Settings!$B$9)) | I19: =IF($D19="","",SUMIFS(Timesheet!$S$5:$S$3004,Timesheet!$B$5:$B$3004,$D19,Timesheet!$A$5:$A$3004,">="&Settings!$B$8,Timesheet!$A$5:$A$3004,"<="&Settings!$B$9)) | J19: =IF($D19="","",G19-H19-I19) | K19: =IF(OR($D19="",N(G19)=0),"",J19/G19)
D20: =IF(Clients!A21="","",Clients!A21) | E20: =IF($D20="","",Clients!B21) | F20: =IF($D20="","",COUNTIFS(Timesheet!$B$5:$B$3004,$D20,Timesheet!$A$5:$A$3004,">="&Settings!$B$8,Timesheet!$A$5:$A$3004,"<="&Settings!$B$9)) | G20: =IF($D20="","",SUMIFS(Timesheet!$O$5:$O$3004,Timesheet!$B$5:$B$3004,$D20,Timesheet!$A$5:$A$3004,">="&Settings!$B$8,Timesheet!$A$5:$A$3004,"<="&Settings!$B$9)) | H20: =IF($D20="","",SUMIFS(Timesheet!$R$5:$R$3004,Timesheet!$B$5:$B$3004,$D20,Timesheet!$A$5:$A$3004,">="&Settings!$B$8,Timesheet!$A$5:$A$3004,"<="&Settings!$B$9)) | I20: =IF($D20="","",SUMIFS(Timesheet!$S$5:$S$3004,Timesheet!$B$5:$B$3004,$D20,Timesheet!$A$5:$A$3004,">="&Settings!$B$8,Timesheet!$A$5:$A$3004,"<="&Settings!$B$9)) | J20: =IF($D20="","",G20-H20-I20) | K20: =IF(OR($D20="",N(G20)=0),"",J20/G20)
D21: =IF(Clients!A22="","",Clients!A22) | E21: =IF($D21="","",Clients!B22) | F21: =IF($D21="","",COUNTIFS(Timesheet!$B$5:$B$3004,$D21,Timesheet!$A$5:$A$3004,">="&Settings!$B$8,Timesheet!$A$5:$A$3004,"<="&Settings!$B$9)) | G21: =IF($D21="","",SUMIFS(Timesheet!$O$5:$O$3004,Timesheet!$B$5:$B$3004,$D21,Timesheet!$A$5:$A$3004,">="&Settings!$B$8,Timesheet!$A$5:$A$3004,"<="&Settings!$B$9)) | H21: =IF($D21="","",SUMIFS(Timesheet!$R$5:$R$3004,Timesheet!$B$5:$B$3004,$D21,Timesheet!$A$5:$A$3004,">="&Settings!$B$8,Timesheet!$A$5:$A$3004,"<="&Settings!$B$9)) | I21: =IF($D21="","",SUMIFS(Timesheet!$S$5:$S$3004,Timesheet!$B$5:$B$3004,$D21,Timesheet!$A$5:$A$3004,">="&Settings!$B$8,Timesheet!$A$5:$A$3004,"<="&Settings!$B$9)) | J21: =IF($D21="","",G21-H21-I21) | K21: =IF(OR($D21="",N(G21)=0),"",J21/G21)
A22: Note: 'Own Cost Est.' per client uses each own worker's cost/hour (Workers col V); Gross Profit at left uses actual payroll. | D22: =IF(Clients!A23="","",Clients!A23) | E22: =IF($D22="","",Clients!B23) | F22: =IF($D22="","",COUNTIFS(Timesheet!$B$5:$B$3004,$D22,Timesheet!$A$5:$A$3004,">="&Settings!$B$8,Timesheet!$A$5:$A$3004,"<="&Settings!$B$9)) | G22: =IF($D22="","",SUMIFS(Timesheet!$O$5:$O$3004,Timesheet!$B$5:$B$3004,$D22,Timesheet!$A$5:$A$3004,">="&Settings!$B$8,Timesheet!$A$5:$A$3004,"<="&Settings!$B$9)) | H22: =IF($D22="","",SUMIFS(Timesheet!$R$5:$R$3004,Timesheet!$B$5:$B$3004,$D22,Timesheet!$A$5:$A$3004,">="&Settings!$B$8,Timesheet!$A$5:$A$3004,"<="&Settings!$B$9)) | I22: =IF($D22="","",SUMIFS(Timesheet!$S$5:$S$3004,Timesheet!$B$5:$B$3004,$D22,Timesheet!$A$5:$A$3004,">="&Settings!$B$8,Timesheet!$A$5:$A$3004,"<="&Settings!$B$9)) | J22: =IF($D22="","",G22-H22-I22) | K22: =IF(OR($D22="",N(G22)=0),"",J22/G22)
D23: =IF(Clients!A24="","",Clients!A24) | E23: =IF($D23="","",Clients!B24) | F23: =IF($D23="","",COUNTIFS(Timesheet!$B$5:$B$3004,$D23,Timesheet!$A$5:$A$3004,">="&Settings!$B$8,Timesheet!$A$5:$A$3004,"<="&Settings!$B$9)) | G23: =IF($D23="","",SUMIFS(Timesheet!$O$5:$O$3004,Timesheet!$B$5:$B$3004,$D23,Timesheet!$A$5:$A$3004,">="&Settings!$B$8,Timesheet!$A$5:$A$3004,"<="&Settings!$B$9)) | H23: =IF($D23="","",SUMIFS(Timesheet!$R$5:$R$3004,Timesheet!$B$5:$B$3004,$D23,Timesheet!$A$5:$A$3004,">="&Settings!$B$8,Timesheet!$A$5:$A$3004,"<="&Settings!$B$9)) | I23: =IF($D23="","",SUMIFS(Timesheet!$S$5:$S$3004,Timesheet!$B$5:$B$3004,$D23,Timesheet!$A$5:$A$3004,">="&Settings!$B$8,Timesheet!$A$5:$A$3004,"<="&Settings!$B$9)) | J23: =IF($D23="","",G23-H23-I23) | K23: =IF(OR($D23="",N(G23)=0),"",J23/G23)
D24: =IF(Clients!A25="","",Clients!A25) | E24: =IF($D24="","",Clients!B25) | F24: =IF($D24="","",COUNTIFS(Timesheet!$B$5:$B$3004,$D24,Timesheet!$A$5:$A$3004,">="&Settings!$B$8,Timesheet!$A$5:$A$3004,"<="&Settings!$B$9)) | G24: =IF($D24="","",SUMIFS(Timesheet!$O$5:$O$3004,Timesheet!$B$5:$B$3004,$D24,Timesheet!$A$5:$A$3004,">="&Settings!$B$8,Timesheet!$A$5:$A$3004,"<="&Settings!$B$9)) | H24: =IF($D24="","",SUMIFS(Timesheet!$R$5:$R$3004,Timesheet!$B$5:$B$3004,$D24,Timesheet!$A$5:$A$3004,">="&Settings!$B$8,Timesheet!$A$5:$A$3004,"<="&Settings!$B$9)) | I24: =IF($D24="","",SUMIFS(Timesheet!$S$5:$S$3004,Timesheet!$B$5:$B$3004,$D24,Timesheet!$A$5:$A$3004,">="&Settings!$B$8,Timesheet!$A$5:$A$3004,"<="&Settings!$B$9)) | J24: =IF($D24="","",G24-H24-I24) | K24: =IF(OR($D24="",N(G24)=0),"",J24/G24)
D25: =IF(Clients!A26="","",Clients!A26) | E25: =IF($D25="","",Clients!B26) | F25: =IF($D25="","",COUNTIFS(Timesheet!$B$5:$B$3004,$D25,Timesheet!$A$5:$A$3004,">="&Settings!$B$8,Timesheet!$A$5:$A$3004,"<="&Settings!$B$9)) | G25: =IF($D25="","",SUMIFS(Timesheet!$O$5:$O$3004,Timesheet!$B$5:$B$3004,$D25,Timesheet!$A$5:$A$3004,">="&Settings!$B$8,Timesheet!$A$5:$A$3004,"<="&Settings!$B$9)) | H25: =IF($D25="","",SUMIFS(Timesheet!$R$5:$R$3004,Timesheet!$B$5:$B$3004,$D25,Timesheet!$A$5:$A$3004,">="&Settings!$B$8,Timesheet!$A$5:$A$3004,"<="&Settings!$B$9)) | I25: =IF($D25="","",SUMIFS(Timesheet!$S$5:$S$3004,Timesheet!$B$5:$B$3004,$D25,Timesheet!$A$5:$A$3004,">="&Settings!$B$8,Timesheet!$A$5:$A$3004,"<="&Settings!$B$9)) | J25: =IF($D25="","",G25-H25-I25) | K25: =IF(OR($D25="",N(G25)=0),"",J25/G25)
D26: =IF(Clients!A27="","",Clients!A27) | E26: =IF($D26="","",Clients!B27) | F26: =IF($D26="","",COUNTIFS(Timesheet!$B$5:$B$3004,$D26,Timesheet!$A$5:$A$3004,">="&Settings!$B$8,Timesheet!$A$5:$A$3004,"<="&Settings!$B$9)) | G26: =IF($D26="","",SUMIFS(Timesheet!$O$5:$O$3004,Timesheet!$B$5:$B$3004,$D26,Timesheet!$A$5:$A$3004,">="&Settings!$B$8,Timesheet!$A$5:$A$3004,"<="&Settings!$B$9)) | H26: =IF($D26="","",SUMIFS(Timesheet!$R$5:$R$3004,Timesheet!$B$5:$B$3004,$D26,Timesheet!$A$5:$A$3004,">="&Settings!$B$8,Timesheet!$A$5:$A$3004,"<="&Settings!$B$9)) | I26: =IF($D26="","",SUMIFS(Timesheet!$S$5:$S$3004,Timesheet!$B$5:$B$3004,$D26,Timesheet!$A$5:$A$3004,">="&Settings!$B$8,Timesheet!$A$5:$A$3004,"<="&Settings!$B$9)) | J26: =IF($D26="","",G26-H26-I26) | K26: =IF(OR($D26="",N(G26)=0),"",J26/G26)
D27: =IF(Clients!A28="","",Clients!A28) | E27: =IF($D27="","",Clients!B28) | F27: =IF($D27="","",COUNTIFS(Timesheet!$B$5:$B$3004,$D27,Timesheet!$A$5:$A$3004,">="&Settings!$B$8,Timesheet!$A$5:$A$3004,"<="&Settings!$B$9)) | G27: =IF($D27="","",SUMIFS(Timesheet!$O$5:$O$3004,Timesheet!$B$5:$B$3004,$D27,Timesheet!$A$5:$A$3004,">="&Settings!$B$8,Timesheet!$A$5:$A$3004,"<="&Settings!$B$9)) | H27: =IF($D27="","",SUMIFS(Timesheet!$R$5:$R$3004,Timesheet!$B$5:$B$3004,$D27,Timesheet!$A$5:$A$3004,">="&Settings!$B$8,Timesheet!$A$5:$A$3004,"<="&Settings!$B$9)) | I27: =IF($D27="","",SUMIFS(Timesheet!$S$5:$S$3004,Timesheet!$B$5:$B$3004,$D27,Timesheet!$A$5:$A$3004,">="&Settings!$B$8,Timesheet!$A$5:$A$3004,"<="&Settings!$B$9)) | J27: =IF($D27="","",G27-H27-I27) | K27: =IF(OR($D27="",N(G27)=0),"",J27/G27)
D28: =IF(Clients!A29="","",Clients!A29) | E28: =IF($D28="","",Clients!B29) | F28: =IF($D28="","",COUNTIFS(Timesheet!$B$5:$B$3004,$D28,Timesheet!$A$5:$A$3004,">="&Settings!$B$8,Timesheet!$A$5:$A$3004,"<="&Settings!$B$9)) | G28: =IF($D28="","",SUMIFS(Timesheet!$O$5:$O$3004,Timesheet!$B$5:$B$3004,$D28,Timesheet!$A$5:$A$3004,">="&Settings!$B$8,Timesheet!$A$5:$A$3004,"<="&Settings!$B$9)) | H28: =IF($D28="","",SUMIFS(Timesheet!$R$5:$R$3004,Timesheet!$B$5:$B$3004,$D28,Timesheet!$A$5:$A$3004,">="&Settings!$B$8,Timesheet!$A$5:$A$3004,"<="&Settings!$B$9)) | I28: =IF($D28="","",SUMIFS(Timesheet!$S$5:$S$3004,Timesheet!$B$5:$B$3004,$D28,Timesheet!$A$5:$A$3004,">="&Settings!$B$8,Timesheet!$A$5:$A$3004,"<="&Settings!$B$9)) | J28: =IF($D28="","",G28-H28-I28) | K28: =IF(OR($D28="",N(G28)=0),"",J28/G28)
D29: =IF(Clients!A30="","",Clients!A30) | E29: =IF($D29="","",Clients!B30) | F29: =IF($D29="","",COUNTIFS(Timesheet!$B$5:$B$3004,$D29,Timesheet!$A$5:$A$3004,">="&Settings!$B$8,Timesheet!$A$5:$A$3004,"<="&Settings!$B$9)) | G29: =IF($D29="","",SUMIFS(Timesheet!$O$5:$O$3004,Timesheet!$B$5:$B$3004,$D29,Timesheet!$A$5:$A$3004,">="&Settings!$B$8,Timesheet!$A$5:$A$3004,"<="&Settings!$B$9)) | H29: =IF($D29="","",SUMIFS(Timesheet!$R$5:$R$3004,Timesheet!$B$5:$B$3004,$D29,Timesheet!$A$5:$A$3004,">="&Settings!$B$8,Timesheet!$A$5:$A$3004,"<="&Settings!$B$9)) | I29: =IF($D29="","",SUMIFS(Timesheet!$S$5:$S$3004,Timesheet!$B$5:$B$3004,$D29,Timesheet!$A$5:$A$3004,">="&Settings!$B$8,Timesheet!$A$5:$A$3004,"<="&Settings!$B$9)) | J29: =IF($D29="","",G29-H29-I29) | K29: =IF(OR($D29="",N(G29)=0),"",J29/G29)
D30: =IF(Clients!A31="","",Clients!A31) | E30: =IF($D30="","",Clients!B31) | F30: =IF($D30="","",COUNTIFS(Timesheet!$B$5:$B$3004,$D30,Timesheet!$A$5:$A$3004,">="&Settings!$B$8,Timesheet!$A$5:$A$3004,"<="&Settings!$B$9)) | G30: =IF($D30="","",SUMIFS(Timesheet!$O$5:$O$3004,Timesheet!$B$5:$B$3004,$D30,Timesheet!$A$5:$A$3004,">="&Settings!$B$8,Timesheet!$A$5:$A$3004,"<="&Settings!$B$9)) | H30: =IF($D30="","",SUMIFS(Timesheet!$R$5:$R$3004,Timesheet!$B$5:$B$3004,$D30,Timesheet!$A$5:$A$3004,">="&Settings!$B$8,Timesheet!$A$5:$A$3004,"<="&Settings!$B$9)) | I30: =IF($D30="","",SUMIFS(Timesheet!$S$5:$S$3004,Timesheet!$B$5:$B$3004,$D30,Timesheet!$A$5:$A$3004,">="&Settings!$B$8,Timesheet!$A$5:$A$3004,"<="&Settings!$B$9)) | J30: =IF($D30="","",G30-H30-I30) | K30: =IF(OR($D30="",N(G30)=0),"",J30/G30)
D31: =IF(Clients!A32="","",Clients!A32) | E31: =IF($D31="","",Clients!B32) | F31: =IF($D31="","",COUNTIFS(Timesheet!$B$5:$B$3004,$D31,Timesheet!$A$5:$A$3004,">="&Settings!$B$8,Timesheet!$A$5:$A$3004,"<="&Settings!$B$9)) | G31: =IF($D31="","",SUMIFS(Timesheet!$O$5:$O$3004,Timesheet!$B$5:$B$3004,$D31,Timesheet!$A$5:$A$3004,">="&Settings!$B$8,Timesheet!$A$5:$A$3004,"<="&Settings!$B$9)) | H31: =IF($D31="","",SUMIFS(Timesheet!$R$5:$R$3004,Timesheet!$B$5:$B$3004,$D31,Timesheet!$A$5:$A$3004,">="&Settings!$B$8,Timesheet!$A$5:$A$3004,"<="&Settings!$B$9)) | I31: =IF($D31="","",SUMIFS(Timesheet!$S$5:$S$3004,Timesheet!$B$5:$B$3004,$D31,Timesheet!$A$5:$A$3004,">="&Settings!$B$8,Timesheet!$A$5:$A$3004,"<="&Settings!$B$9)) | J31: =IF($D31="","",G31-H31-I31) | K31: =IF(OR($D31="",N(G31)=0),"",J31/G31)
D32: =IF(Clients!A33="","",Clients!A33) | E32: =IF($D32="","",Clients!B33) | F32: =IF($D32="","",COUNTIFS(Timesheet!$B$5:$B$3004,$D32,Timesheet!$A$5:$A$3004,">="&Settings!$B$8,Timesheet!$A$5:$A$3004,"<="&Settings!$B$9)) | G32: =IF($D32="","",SUMIFS(Timesheet!$O$5:$O$3004,Timesheet!$B$5:$B$3004,$D32,Timesheet!$A$5:$A$3004,">="&Settings!$B$8,Timesheet!$A$5:$A$3004,"<="&Settings!$B$9)) | H32: =IF($D32="","",SUMIFS(Timesheet!$R$5:$R$3004,Timesheet!$B$5:$B$3004,$D32,Timesheet!$A$5:$A$3004,">="&Settings!$B$8,Timesheet!$A$5:$A$3004,"<="&Settings!$B$9)) | I32: =IF($D32="","",SUMIFS(Timesheet!$S$5:$S$3004,Timesheet!$B$5:$B$3004,$D32,Timesheet!$A$5:$A$3004,">="&Settings!$B$8,Timesheet!$A$5:$A$3004,"<="&Settings!$B$9)) | J32: =IF($D32="","",G32-H32-I32) | K32: =IF(OR($D32="",N(G32)=0),"",J32/G32)
D33: =IF(Clients!A34="","",Clients!A34) | E33: =IF($D33="","",Clients!B34) | F33: =IF($D33="","",COUNTIFS(Timesheet!$B$5:$B$3004,$D33,Timesheet!$A$5:$A$3004,">="&Settings!$B$8,Timesheet!$A$5:$A$3004,"<="&Settings!$B$9)) | G33: =IF($D33="","",SUMIFS(Timesheet!$O$5:$O$3004,Timesheet!$B$5:$B$3004,$D33,Timesheet!$A$5:$A$3004,">="&Settings!$B$8,Timesheet!$A$5:$A$3004,"<="&Settings!$B$9)) | H33: =IF($D33="","",SUMIFS(Timesheet!$R$5:$R$3004,Timesheet!$B$5:$B$3004,$D33,Timesheet!$A$5:$A$3004,">="&Settings!$B$8,Timesheet!$A$5:$A$3004,"<="&Settings!$B$9)) | I33: =IF($D33="","",SUMIFS(Timesheet!$S$5:$S$3004,Timesheet!$B$5:$B$3004,$D33,Timesheet!$A$5:$A$3004,">="&Settings!$B$8,Timesheet!$A$5:$A$3004,"<="&Settings!$B$9)) | J33: =IF($D33="","",G33-H33-I33) | K33: =IF(OR($D33="",N(G33)=0),"",J33/G33)

Sheet Settings
A1: Settings | D1: « HOME
A2: Yellow cells are inputs. Change the payroll month here every month.
A4: Company Name | B4: Gulf Star Manpower Services LLC | D4: Trades | F4: Source | H4: Pay Basis | J4: Deduction Types | L4: Status
A5: Company TRN (VAT) | B5: 100123456700003 | D5: Helper | F5: Own | H5: Monthly | J5: Advance | L5: Active
A6: Employer MOHRE ID (13 digits) | B6: 0000001234567 | D6: Mason | F6: Supplier | H6: Hourly | J6: Fine | L6: Inactive
A7: Employer Bank Routing Code | B7: 803320101 | D7: Carpenter | J7: Accommodation
A8: Payroll Month (1st day) | B8: 46296 | D8: Electrician | J8: Other
A9: Month End | B9: =EOMONTH(B8,0) -> 46326 | D9: Plumber
A10: Salary Day Divisor | B10: 30 | D10: Steel Fixer
A11: Standard Working Days / Month | B11: 26 | D11: Driver
A12: Normal Hours / Day | B12: 8 | D12: Cleaner
A13: OT Multiplier | B13: 1.25 | D13: Security Guard
A14: VAT Rate | B14: 0.05
A15: Document Expiry Alert (days) | B15: 30
A17: Note: OT multiplier 1.25 and divisor 30 follow common UAE practice - confirm with your HR / legal advisor.

Sheet Clients
A1: Clients (Customers) | C1: « HOME
A2: One row per client. Client ID must be unique.
A4: Client ID | B4: Client Name | C4: TRN | D4: Emirate | E4: Payment Terms (days) | F4: Contact Person | G4: Phone
A5: C001 | B5: Al Waha Contracting LLC | C5: 100555111200003 | D5: Dubai | E5: 30 | F5: Mr. Al | G5: +971 4 000 0000
A6: C002 | B6: Blue Creek Facilities Mgmt | C6: 100555222300003 | D6: Abu Dhabi | E6: 45 | F6: Mr. Blue | G6: +971 4 000 0001
A7: C003 | B7: Sandline Construction Co. | C7: 100555333400003 | D7: Sharjah | E7: 30 | F7: Mr. Sandline | G7: +971 4 000 0002
A8: C004 | B8: Marina Hospitality Group | C8: 100555444500003 | D8: Dubai | E8: 60 | F8: Mr. Marina | G8: +971 4 000 0003

Sheet Suppliers
A1: Suppliers (Manpower Agencies) | D1: « HOME
A2: Companies that supply workers to you.
A4: Supplier ID | B4: Supplier Name | C4: TRN | D4: Payment Terms (days) | E4: Contact Person | F4: Bank IBAN
A5: S001 | B5: Desert Falcon Manpower Supply | C5: 100777111200003 | D5: 30 | E5: Mr. Desert | F5: AE07 0331 2345 6789 0123 450
A6: S002 | B6: Emirates Link Labour Services | C6: 100777222300003 | D6: 45 | E6: Mr. Emirates | F6: AE07 0331 2345 6789 0123 451
A7: S003 | B7: Oasis Workforce Solutions | C7: 100777333400003 | D7: 30 | E7: Mr. Oasis | F7: AE07 0331 2345 6789 0123 452

Sheet ClientRates
A1: ClientRates | C1: « HOME
A2: Selling rate charged to each client, per trade.
A4: Key (auto) | B4: Client ID | C4: Trade | D4: Normal Rate / hr (AED) | E4: OT Rate / hr (AED)
A5: =IF(B5="","",B5&"|"&C5) -> C001|Helper | B5: C001 | C5: Helper | D5: 16 | E5: 20
A6: =IF(B6="","",B6&"|"&C6) -> C001|Mason | B6: C001 | C6: Mason | D6: 22 | E6: 27.5
A7: =IF(B7="","",B7&"|"&C7) -> C001|Carpenter | B7: C001 | C7: Carpenter | D7: 22 | E7: 27.5
A8: =IF(B8="","",B8&"|"&C8) -> C001|Electrician | B8: C001 | C8: Electrician | D8: 26 | E8: 32.5
A9: =IF(B9="","",B9&"|"&C9) -> C001|Plumber | B9: C001 | C9: Plumber | D9: 25 | E9: 31.25
A10: =IF(B10="","",B10&"|"&C10) -> C001|Steel Fixer | B10: C001 | C10: Steel Fixer | D10: 23 | E10: 28.75
A11: =IF(B11="","",B11&"|"&C11) -> C001|Driver | B11: C001 | C11: Driver | D11: 24 | E11: 30
A12: =IF(B12="","",B12&"|"&C12) -> C001|Cleaner | B12: C001 | C12: Cleaner | D12: 15 | E12: 18.75
A13: =IF(B13="","",B13&"|"&C13) -> C001|Security Guard | B13: C001 | C13: Security Guard | D13: 17 | E13: 21.25
A14: =IF(B14="","",B14&"|"&C14) -> C002|Helper | B14: C002 | C14: Helper | D14: 17.6 | E14: 22
A15: =IF(B15="","",B15&"|"&C15) -> C002|Mason | B15: C002 | C15: Mason | D15: 24.2 | E15: 30.25
A16: =IF(B16="","",B16&"|"&C16) -> C002|Carpenter | B16: C002 | C16: Carpenter | D16: 24.2 | E16: 30.25
... A40: =IF(B40="","",B40&"|"&C40) -> C004|Security Guard | B40: C004 | C40: Security Guard | D40: 17.85 | E40: 22.31
A41: =IF(B41="","",B41&"|"&C41)
A42: =IF(B42="","",B42&"|"&C42)
A43: =IF(B43="","",B43&"|"&C43)
A44: =IF(B44="","",B44&"|"&C44)
A45: =IF(B45="","",B45&"|"&C45)
A46: =IF(B46="","",B46&"|"&C46)
A47: =IF(B47="","",B47&"|"&C47)
A48: =IF(B48="","",B48&"|"&C48)
A49: =IF(B49="","",B49&"|"&C49)
A50: =IF(B50="","",B50&"|"&C50)
A51: =IF(B51="","",B51&"|"&C51)
A52: =IF(B52="","",B52&"|"&C52)
... A100: =IF(B100="","",B100&"|"&C100)

Sheet SupplierRates
A1: SupplierRates | C1: « HOME
A2: Cost rate charged by each supplier, per trade.
A4: Key (auto) | B4: Supplier ID | C4: Trade | D4: Normal Rate / hr (AED) | E4: OT Rate / hr (AED)
A5: =IF(B5="","",B5&"|"&C5) -> S001|Helper | B5: S001 | C5: Helper | D5: 11.52 | E5: 14.4
A6: =IF(B6="","",B6&"|"&C6) -> S001|Mason | B6: S001 | C6: Mason | D6: 15.84 | E6: 19.8
A7: =IF(B7="","",B7&"|"&C7) -> S001|Carpenter | B7: S001 | C7: Carpenter | D7: 15.84 | E7: 19.8
A8: =IF(B8="","",B8&"|"&C8) -> S001|Electrician | B8: S001 | C8: Electrician | D8: 18.72 | E8: 23.4
A9: =IF(B9="","",B9&"|"&C9) -> S001|Plumber | B9: S001 | C9: Plumber | D9: 18 | E9: 22.5
A10: =IF(B10="","",B10&"|"&C10) -> S001|Steel Fixer | B10: S001 | C10: Steel Fixer | D10: 16.56 | E10: 20.7
A11: =IF(B11="","",B11&"|"&C11) -> S001|Driver | B11: S001 | C11: Driver | D11: 17.28 | E11: 21.6
A12: =IF(B12="","",B12&"|"&C12) -> S001|Cleaner | B12: S001 | C12: Cleaner | D12: 10.8 | E12: 13.5
A13: =IF(B13="","",B13&"|"&C13) -> S001|Security Guard | B13: S001 | C13: Security Guard | D13: 12.24 | E13: 15.3
A14: =IF(B14="","",B14&"|"&C14) -> S002|Helper | B14: S002 | C14: Helper | D14: 12 | E14: 15
A15: =IF(B15="","",B15&"|"&C15) -> S002|Mason | B15: S002 | C15: Mason | D15: 16.5 | E15: 20.62
A16: =IF(B16="","",B16&"|"&C16) -> S002|Carpenter | B16: S002 | C16: Carpenter | D16: 16.5 | E16: 20.62
... A31: =IF(B31="","",B31&"|"&C31) -> S003|Security Guard | B31: S003 | C31: Security Guard | D31: 11.9 | E31: 14.88
A32: =IF(B32="","",B32&"|"&C32)
A33: =IF(B33="","",B33&"|"&C33)
A34: =IF(B34="","",B34&"|"&C34)
A35: =IF(B35="","",B35&"|"&C35)
A36: =IF(B36="","",B36&"|"&C36)
A37: =IF(B37="","",B37&"|"&C37)
A38: =IF(B38="","",B38&"|"&C38)
A39: =IF(B39="","",B39&"|"&C39)
A40: =IF(B40="","",B40&"|"&C40)
A41: =IF(B41="","",B41&"|"&C41)
A42: =IF(B42="","",B42&"|"&C42)
A43: =IF(B43="","",B43&"|"&C43)
... A91: =IF(B91="","",B91&"|"&C91)

Sheet Workers
A1: Workers Master | C1: « HOME
A2: Own + supplier workers. Salary / bank fields are needed only for Own workers. Columns R-V are automatic.
A4: Worker ID | B4: Name | C4: Source | D4: Supplier ID | E4: Trade | F4: Nationality | G4: Passport No | H4: Labour Card / Person ID | I4: Visa Expiry | J4: Emirates ID Expiry | K4: Pay Basis | L4: Basic Salary / Month | M4: Allowances / Month | N4: Hourly Rate | O4: Bank Routing Code | P4: IBAN | Q4: Status | R4: Days to Visa Expiry | S4: Days to EID Expiry | T4: Document Alert | U4: Own Seq (auto) | V4: Own Cost / hr
A5: W0001 | B5: Marlon Khan | C5: Own | E5: Steel Fixer | F5: Pakistan | G5: P9648511 | H5: 96921334349946 | I5: 46391 | J5: 46396 | K5: Monthly | L5: 1400 | M5: 400 | O5: 402320106 | P5: AE96 1884 8481 7428 7521 508 | Q5: Active | R5: =IF(I5="","",I5-TODAY()) -> 64 | S5: =IF(J5="","",J5-TODAY()) -> 69 | T5: =IF(A5="","",IF(OR(AND(R5<>"",R5<0),AND(S5<>"",S5<0)),"EXPIRED",IF(OR(AND(R5<>"",R5<=Settings!$B$15),AND(S5<>"",S5<=Settings!$B$15)),"EXPIRING SOON","OK"))) -> OK | U5: =IF(AND(C5="Own",Q5="Active"),COUNTIFS($C$5:C5,"Own",$Q$5:Q5,"Active"),"") -> 1 | V5: =IF(C5<>"Own","",IF(K5="Hourly",N5,(L5+M5)/(Settings!$B$11*Settings!$B$12))) -> 8.6538462
A6: W0002 | B6: Rohan Ali | C6: Own | E6: Helper | F6: Philippines | G6: P3537804 | H6: 24278776051635 | I6: 46339 | J6: 46339 | K6: Monthly | L6: 1200 | M6: 500 | O6: 600310101 | P6: AE88 1417 2152 4407 7164 252 | Q6: Active | R6: =IF(I6="","",I6-TODAY()) -> 12 | S6: =IF(J6="","",J6-TODAY()) -> 12 | T6: =IF(A6="","",IF(OR(AND(R6<>"",R6<0),AND(S6<>"",S6<0)),"EXPIRED",IF(OR(AND(R6<>"",R6<=Settings!$B$15),AND(S6<>"",S6<=Settings!$B$15)),"EXPIRING SOON","OK"))) -> EXPIRING SOON | U6: =IF(AND(C6="Own",Q6="Active"),COUNTIFS($C$5:C6,"Own",$Q$5:Q6,"Active"),"") -> 2 | V6: =IF(C6<>"Own","",IF(K6="Hourly",N6,(L6+M6)/(Settings!$B$11*Settings!$B$12))) -> 8.1730769
A7: W0003 | B7: Ronel Thapa | C7: Own | E7: Mason | F7: Nepal | G7: P5441883 | H7: 32723349357046 | I7: 46352 | J7: 46352 | K7: Monthly | L7: 1500 | M7: 500 | O7: 402320106 | P7: AE12 4362 9654 6926 3401 806 | Q7: Active | R7: =IF(I7="","",I7-TODAY()) -> 25 | S7: =IF(J7="","",J7-TODAY()) -> 25 | T7: =IF(A7="","",IF(OR(AND(R7<>"",R7<0),AND(S7<>"",S7<0)),"EXPIRED",IF(OR(AND(R7<>"",R7<=Settings!$B$15),AND(S7<>"",S7<=Settings!$B$15)),"EXPIRING SOON","OK"))) -> EXPIRING SOON | U7: =IF(AND(C7="Own",Q7="Active"),COUNTIFS($C$5:C7,"Own",$Q$5:Q7,"Active"),"") -> 3 | V7: =IF(C7<>"Own","",IF(K7="Hourly",N7,(L7+M7)/(Settings!$B$11*Settings!$B$12))) -> 9.6153846
A8: W0004 | B8: Tariq Varghese | C8: Own | E8: Helper | F8: Nepal | G8: P4742018 | H8: 41910762301181 | I8: 46615 | J8: 46655 | K8: Monthly | L8: 2000 | M8: 300 | O8: 803320101 | P8: AE76 9073 6825 1474 1457 909 | Q8: Active | R8: =IF(I8="","",I8-TODAY()) -> 288 | S8: =IF(J8="","",J8-TODAY()) -> 328 | T8: =IF(A8="","",IF(OR(AND(R8<>"",R8<0),AND(S8<>"",S8<0)),"EXPIRED",IF(OR(AND(R8<>"",R8<=Settings!$B$15),AND(S8<>"",S8<=Settings!$B$15)),"EXPIRING SOON","OK"))) -> OK | U8: =IF(AND(C8="Own",Q8="Active"),COUNTIFS($C$5:C8,"Own",$Q$5:Q8,"Active"),"") -> 4 | V8: =IF(C8<>"Own","",IF(K8="Hourly",N8,(L8+M8)/(Settings!$B$11*Settings!$B$12))) -> 11.057692
A9: W0005 | B9: Joseph Ahmed | C9: Own | E9: Helper | F9: Pakistan | G9: P9097578 | H9: 95890327812981 | I9: 46652 | J9: 46657 | K9: Monthly | L9: 1200 | M9: 400 | O9: 803320101 | P9: AE71 6636 2389 2964 7365 901 | Q9: Active | R9: =IF(I9="","",I9-TODAY()) -> 325 | S9: =IF(J9="","",J9-TODAY()) -> 330 | T9: =IF(A9="","",IF(OR(AND(R9<>"",R9<0),AND(S9<>"",S9<0)),"EXPIRED",IF(OR(AND(R9<>"",R9<=Settings!$B$15),AND(S9<>"",S9<=Settings!$B$15)),"EXPIRING SOON","OK"))) -> OK | U9: =IF(AND(C9="Own",Q9="Active"),COUNTIFS($C$5:C9,"Own",$Q$5:Q9,"Active"),"") -> 5 | V9: =IF(C9<>"Own","",IF(K9="Hourly",N9,(L9+M9)/(Settings!$B$11*Settings!$B$12))) -> 7.6923077
A10: W0006 | B10: Dinesh Shrestha | C10: Own | E10: Driver | F10: Pakistan | G10: P8807342 | H10: 96071772425721 | I10: 46352 | J10: 46352 | K10: Monthly | L10: 1200 | M10: 300 | O10: 402320106 | P10: AE70 6741 3554 9989 9983 234 | Q10: Active | R10: =IF(I10="","",I10-TODAY()) -> 25 | S10: =IF(J10="","",J10-TODAY()) -> 25 | T10: =IF(A10="","",IF(OR(AND(R10<>"",R10<0),AND(S10<>"",S10<0)),"EXPIRED",IF(OR(AND(R10<>"",R10<=Settings!$B$15),AND(S10<>"",S10<=Settings!$B$15)),"EXPIRING SOON","OK"))) -> EXPIRING SOON | U10: =IF(AND(C10="Own",Q10="Active"),COUNTIFS($C$5:C10,"Own",$Q$5:Q10,"Active"),"") -> 6 | V10: =IF(C10<>"Own","",IF(K10="Hourly",N10,(L10+M10)/(Settings!$B$11*Settings!$B$12))) -> 7.2115385
A11: W0007 | B11: Rahul Kumar | C11: Own | E11: Mason | F11: Nepal | G11: P5351419 | H11: 68972238951406 | I11: 46686 | J11: 46726 | K11: Monthly | L11: 2000 | M11: 400 | O11: 803320101 | P11: AE17 6796 8506 9466 7891 946 | Q11: Active | R11: =IF(I11="","",I11-TODAY()) -> 359 | S11: =IF(J11="","",J11-TODAY()) -> 399 | T11: =IF(A11="","",IF(OR(AND(R11<>"",R11<0),AND(S11<>"",S11<0)),"EXPIRED",IF(OR(AND(R11<>"",R11<=Settings!$B$15),AND(S11<>"",S11<=Settings!$B$15)),"EXPIRING SOON","OK"))) -> OK | U11: =IF(AND(C11="Own",Q11="Active"),COUNTIFS($C$5:C11,"Own",$Q$5:Q11,"Active"),"") -> 7 | V11: =IF(C11<>"Own","",IF(K11="Hourly",N11,(L11+M11)/(Settings!$B$11*Settings!$B$12))) -> 11.538462
A12: W0008 | B12: Mohan Nair | C12: Own | E12: Helper | F12: India | G12: P2036081 | H12: 84691707568212 | I12: 46406 | J12: 46446 | K12: Hourly | N12: 9 | O12: 402320106 | P12: AE71 2738 1930 5071 4134 383 | Q12: Active | R12: =IF(I12="","",I12-TODAY()) -> 79 | S12: =IF(J12="","",J12-TODAY()) -> 119 | T12: =IF(A12="","",IF(OR(AND(R12<>"",R12<0),AND(S12<>"",S12<0)),"EXPIRED",IF(OR(AND(R12<>"",R12<=Settings!$B$15),AND(S12<>"",S12<=Settings!$B$15)),"EXPIRING SOON","OK"))) -> OK | U12: =IF(AND(C12="Own",Q12="Active"),COUNTIFS($C$5:C12,"Own",$Q$5:Q12,"Active"),"") -> 8 | V12: =IF(C12<>"Own","",IF(K12="Hourly",N12,(L12+M12)/(Settings!$B$11*Settings!$B$12))) -> 9
A13: W0009 | B13: Anwar Shrestha | C13: Own | E13: Electrician | F13: Nepal | G13: P8589103 | H13: 85052441044367 | I13: 46487 | J13: 46527 | K13: Monthly | L13: 2500 | M13: 500 | O13: 600310101 | P13: AE74 5057 9572 5253 4319 960 | Q13: Active | R13: =IF(I13="","",I13-TODAY()) -> 160 | S13: =IF(J13="","",J13-TODAY()) -> 200 | T13: =IF(A13="","",IF(OR(AND(R13<>"",R13<0),AND(S13<>"",S13<0)),"EXPIRED",IF(OR(AND(R13<>"",R13<=Settings!$B$15),AND(S13<>"",S13<=Settings!$B$15)),"EXPIRING SOON","OK"))) -> OK | U13: =IF(AND(C13="Own",Q13="Active"),COUNTIFS($C$5:C13,"Own",$Q$5:Q13,"Active"),"") -> 9 | V13: =IF(C13<>"Own","",IF(K13="Hourly",N13,(L13+M13)/(Settings!$B$11*Settings!$B$12))) -> 14.423077
A14: W0010 | B14: Hari Nair | C14: Own | E14: Helper | F14: Nepal | G14: P3398789 | H14: 40904298604831 | I14: 46512 | J14: 46512 | K14: Monthly | L14: 2000 | M14: 500 | O14: 402320106 | P14: AE22 7525 8983 3667 4665 265 | Q14: Active | R14: =IF(I14="","",I14-TODAY()) -> 185 | S14: =IF(J14="","",J14-TODAY()) -> 185 | T14: =IF(A14="","",IF(OR(AND(R14<>"",R14<0),AND(S14<>"",S14<0)),"EXPIRED",IF(OR(AND(R14<>"",R14<=Settings!$B$15),AND(S14<>"",S14<=Settings!$B$15)),"EXPIRING SOON","OK"))) -> OK | U14: =IF(AND(C14="Own",Q14="Active"),COUNTIFS($C$5:C14,"Own",$Q$5:Q14,"Active"),"") -> 10 | V14: =IF(C14<>"Own","",IF(K14="Hourly",N14,(L14+M14)/(Settings!$B$11*Settings!$B$12))) -> 12.019231
A15: W0011 | B15: Dinesh Menon | C15: Own | E15: Driver | F15: India | G15: P7448231 | H15: 82822594276261 | I15: 46587 | J15: 46592 | K15: Monthly | L15: 1200 | M15: 300 | O15: 402320106 | P15: AE47 9392 2053 2848 4744 997 | Q15: Active | R15: =IF(I15="","",I15-TODAY()) -> 260 | S15: =IF(J15="","",J15-TODAY()) -> 265 | T15: =IF(A15="","",IF(OR(AND(R15<>"",R15<0),AND(S15<>"",S15<0)),"EXPIRED",IF(OR(AND(R15<>"",R15<=Settings!$B$15),AND(S15<>"",S15<=Settings!$B$15)),"EXPIRING SOON","OK"))) -> OK | U15: =IF(AND(C15="Own",Q15="Active"),COUNTIFS($C$5:C15,"Own",$Q$5:Q15,"Active"),"") -> 11 | V15: =IF(C15<>"Own","",IF(K15="Hourly",N15,(L15+M15)/(Settings!$B$11*Settings!$B$12))) -> 7.2115385
A16: W0012 | B16: Imran Ali | C16: Own | E16: Helper | F16: Nepal | G16: P2500926 | H16: 18097211916423 | I16: 46819 | J16: 46824 | K16: Monthly | L16: 2000 | M16: 300 | O16: 402320106 | P16: AE33 7968 2186 5406 1275 749 | Q16: Active | R16: =IF(I16="","",I16-TODAY()) -> 492 | S16: =IF(J16="","",J16-TODAY()) -> 497 | T16: =IF(A16="","",IF(OR(AND(R16<>"",R16<0),AND(S16<>"",S16<0)),"EXPIRED",IF(OR(AND(R16<>"",R16<=Settings!$B$15),AND(S16<>"",S16<=Settings!$B$15)),"EXPIRING SOON","OK"))) -> OK | U16: =IF(AND(C16="Own",Q16="Active"),COUNTIFS($C$5:C16,"Own",$Q$5:Q16,"Active"),"") -> 12 | V16: =IF(C16<>"Own","",IF(K16="Hourly",N16,(L16+M16)/(Settings!$B$11*Settings!$B$12))) -> 11.057692
A17: W0013 | B17: Suresh Shrestha | C17: Own | E17: Plumber | F17: Philippines | G17: P3168032 | H17: 84152795932475 | I17: 46814 | J17: 46819 | K17: Monthly | L17: 1800 | M17: 300 | O17: 402320106 | P17: AE40 2793 3645 5290 1825 285 | Q17: Active | R17: =IF(I17="","",I17-TODAY()) -> 487 | S17: =IF(J17="","",J17-TODAY()) -> 492 | T17: =IF(A17="","",IF(OR(AND(R17<>"",R17<0),AND(S17<>"",S17<0)),"EXPIRED",IF(OR(AND(R17<>"",R17<=Settings!$B$15),AND(S17<>"",S17<=Settings!$B$15)),"EXPIRING SOON","OK"))) -> OK | U17: =IF(AND(C17="Own",Q17="Active"),COUNTIFS($C$5:C17,"Own",$Q$5:Q17,"Active"),"") -> 13 | V17: =IF(C17<>"Own","",IF(K17="Hourly",N17,(L17+M17)/(Settings!$B$11*Settings!$B$12))) -> 10.096154
A18: W0014 | B18: Prakash Varghese | C18: Own | E18: Security Guard | F18: India | G18: P9483466 | H18: 82371012647049 | I18: 46317 | J18: 46317 | K18: Monthly | L18: 1200 | M18: 500 | O18: 600310101 | P18: AE41 8324 2741 8080 9110 659 | Q18: Active | R18: =IF(I18="","",I18-TODAY()) -> -10 | S18: =IF(J18="","",J18-TODAY()) -> -10 | T18: =IF(A18="","",IF(OR(AND(R18<>"",R18<0),AND(S18<>"",S18<0)),"EXPIRED",IF(OR(AND(R18<>"",R18<=Settings!$B$15),AND(S18<>"",S18<=Settings!$B$15)),"EXPIRING SOON","OK"))) -> EXPIRED | U18: =IF(AND(C18="Own",Q18="Active"),COUNTIFS($C$5:C18,"Own",$Q$5:Q18,"Active"),"") -> 14 | V18: =IF(C18<>"Own","",IF(K18="Hourly",N18,(L18+M18)/(Settings!$B$11*Settings!$B$12))) -> 8.1730769
A19: W0015 | B19: Rohan Gurung | C19: Own | E19: Plumber | F19: Nepal | G19: P8226629 | H19: 17796066780717 | I19: 46742 | J19: 46782 | K19: Monthly | L19: 2000 | M19: 500 | O19: 803320101 | P19: AE95 7240 9289 5619 4968 809 | Q19: Active | R19: =IF(I19="","",I19-TODAY()) -> 415 | S19: =IF(J19="","",J19-TODAY()) -> 455 | T19: =IF(A19="","",IF(OR(AND(R19<>"",R19<0),AND(S19<>"",S19<0)),"EXPIRED",IF(OR(AND(R19<>"",R19<=Settings!$B$15),AND(S19<>"",S19<=Settings!$B$15)),"EXPIRING SOON","OK"))) -> OK | U19: =IF(AND(C19="Own",Q19="Active"),COUNTIFS($C$5:C19,"Own",$Q$5:Q19,"Active"),"") -> 15 | V19: =IF(C19<>"Own","",IF(K19="Hourly",N19,(L19+M19)/(Settings!$B$11*Settings!$B$12))) -> 12.019231
A20: W0016 | B20: Sanjay Kumar | C20: Own | E20: Carpenter | F20: Pakistan | G20: P6982485 | H20: 10151109653521 | I20: 46317 | J20: 46322 | K20: Hourly | N20: 11 | O20: 600310101 | P20: AE58 2374 8776 5569 9237 771 | Q20: Active | R20: =IF(I20="","",I20-TODAY()) -> -10 | S20: =IF(J20="","",J20-TODAY()) -> -5 | T20: =IF(A20="","",IF(OR(AND(R20<>"",R20<0),AND(S20<>"",S20<0)),"EXPIRED",IF(OR(AND(R20<>"",R20<=Settings!$B$15),AND(S20<>"",S20<=Settings!$B$15)),"EXPIRING SOON","OK"))) -> EXPIRED | U20: =IF(AND(C20="Own",Q20="Active"),COUNTIFS($C$5:C20,"Own",$Q$5:Q20,"Active"),"") -> 16 | V20: =IF(C20<>"Own","",IF(K20="Hourly",N20,(L20+M20)/(Settings!$B$11*Settings!$B$12))) -> 11
A21: W0017 | B21: Prakash Khan | C21: Own | E21: Electrician | F21: Pakistan | G21: P2417384 | H21: 31851722182217 | I21: 46392 | J21: 46432 | K21: Monthly | L21: 1500 | M21: 300 | O21: 402320106 | P21: AE86 7381 6343 9096 3448 390 | Q21: Active | R21: =IF(I21="","",I21-TODAY()) -> 65 | S21: =IF(J21="","",J21-TODAY()) -> 105 | T21: =IF(A21="","",IF(OR(AND(R21<>"",R21<0),AND(S21<>"",S21<0)),"EXPIRED",IF(OR(AND(R21<>"",R21<=Settings!$B$15),AND(S21<>"",S21<=Settings!$B$15)),"EXPIRING SOON","OK"))) -> OK | U21: =IF(AND(C21="Own",Q21="Active"),COUNTIFS($C$5:C21,"Own",$Q$5:Q21,"Active"),"") -> 17 | V21: =IF(C21<>"Own","",IF(K21="Hourly",N21,(L21+M21)/(Settings!$B$11*Settings!$B$12))) -> 8.6538462
A22: W0018 | B22: Nabin Pillai | C22: Own | E22: Security Guard | F22: India | G22: P3232933 | H22: 60764954880477 | I22: 46339 | J22: 46339 | K22: Monthly | L22: 2500 | M22: 300 | O22: 803320101 | P22: AE58 8395 1831 1308 9707 797 | Q22: Active | R22: =IF(I22="","",I22-TODAY()) -> 12 | S22: =IF(J22="","",J22-TODAY()) -> 12 | T22: =IF(A22="","",IF(OR(AND(R22<>"",R22<0),AND(S22<>"",S22<0)),"EXPIRED",IF(OR(AND(R22<>"",R22<=Settings!$B$15),AND(S22<>"",S22<=Settings!$B$15)),"EXPIRING SOON","OK"))) -> EXPIRING SOON | U22: =IF(AND(C22="Own",Q22="Active"),COUNTIFS($C$5:C22,"Own",$Q$5:Q22,"Active"),"") -> 18 | V22: =IF(C22<>"Own","",IF(K22="Hourly",N22,(L22+M22)/(Settings!$B$11*Settings!$B$12))) -> 13.461538
A23: W0019 | B23: Faisal Ahmed | C23: Own | E23: Helper | F23: Pakistan | G23: P4442978 | H23: 79516022831268 | I23: 46645 | J23: 46650 | K23: Monthly | L23: 2000 | M23: 300 | O23: 600310101 | P23: AE19 8848 5707 1765 4248 179 | Q23: Active | R23: =IF(I23="","",I23-TODAY()) -> 318 | S23: =IF(J23="","",J23-TODAY()) -> 323 | T23: =IF(A23="","",IF(OR(AND(R23<>"",R23<0),AND(S23<>"",S23<0)),"EXPIRED",IF(OR(AND(R23<>"",R23<=Settings!$B$15),AND(S23<>"",S23<=Settings!$B$15)),"EXPIRING SOON","OK"))) -> OK | U23: =IF(AND(C23="Own",Q23="Active"),COUNTIFS($C$5:C23,"Own",$Q$5:Q23,"Active"),"") -> 19 | V23: =IF(C23<>"Own","",IF(K23="Hourly",N23,(L23+M23)/(Settings!$B$11*Settings!$B$12))) -> 11.057692
A24: W0020 | B24: Shafi Nair | C24: Own | E24: Cleaner | F24: Bangladesh | G24: P5879761 | H24: 82695366062236 | I24: 46449 | J24: 46449 | K24: Monthly | L24: 2500 | M24: 500 | O24: 600310101 | P24: AE69 8633 8640 2941 9996 304 | Q24: Active | R24: =IF(I24="","",I24-TODAY()) -> 122 | S24: =IF(J24="","",J24-TODAY()) -> 122 | T24: =IF(A24="","",IF(OR(AND(R24<>"",R24<0),AND(S24<>"",S24<0)),"EXPIRED",IF(OR(AND(R24<>"",R24<=Settings!$B$15),AND(S24<>"",S24<=Settings!$B$15)),"EXPIRING SOON","OK"))) -> OK | U24: =IF(AND(C24="Own",Q24="Active"),COUNTIFS($C$5:C24,"Own",$Q$5:Q24,"Active"),"") -> 20 | V24: =IF(C24<>"Own","",IF(K24="Hourly",N24,(L24+M24)/(Settings!$B$11*Settings!$B$12))) -> 14.423077
A25: W0021 | B25: Sanjay Ali | C25: Own | E25: Driver | F25: Pakistan | G25: P9792363 | H25: 28663177171983 | I25: 46847 | J25: 46847 | K25: Monthly | L25: 1500 | M25: 400 | O25: 402320106 | P25: AE90 9335 5580 2846 6983 336 | Q25: Active | R25: =IF(I25="","",I25-TODAY()) -> 520 | S25: =IF(J25="","",J25-TODAY()) -> 520 | T25: =IF(A25="","",IF(OR(AND(R25<>"",R25<0),AND(S25<>"",S25<0)),"EXPIRED",IF(OR(AND(R25<>"",R25<=Settings!$B$15),AND(S25<>"",S25<=Settings!$B$15)),"EXPIRING SOON","OK"))) -> OK | U25: =IF(AND(C25="Own",Q25="Active"),COUNTIFS($C$5:C25,"Own",$Q$5:Q25,"Active"),"") -> 21 | V25: =IF(C25<>"Own","",IF(K25="Hourly",N25,(L25+M25)/(Settings!$B$11*Settings!$B$12))) -> 9.1346154
A26: W0022 | B26: Jamal Varghese | C26: Own | E26: Cleaner | F26: India | G26: P6558700 | H26: 55672689704836 | I26: 46549 | J26: 46554 | K26: Monthly | L26: 1500 | M26: 400 | O26: 600310101 | P26: AE60 2966 4207 1192 5748 359 | Q26: Active | R26: =IF(I26="","",I26-TODAY()) -> 222 | S26: =IF(J26="","",J26-TODAY()) -> 227 | T26: =IF(A26="","",IF(OR(AND(R26<>"",R26<0),AND(S26<>"",S26<0)),"EXPIRED",IF(OR(AND(R26<>"",R26<=Settings!$B$15),AND(S26<>"",S26<=Settings!$B$15)),"EXPIRING SOON","OK"))) -> OK | U26: =IF(AND(C26="Own",Q26="Active"),COUNTIFS($C$5:C26,"Own",$Q$5:Q26,"Active"),"") -> 22 | V26: =IF(C26<>"Own","",IF(K26="Hourly",N26,(L26+M26)/(Settings!$B$11*Settings!$B$12))) -> 9.1346154
A27: W0023 | B27: Bikash Ali | C27: Own | E27: Electrician | F27: Pakistan | G27: P5458176 | H27: 81912511076662 | I27: 46436 | J27: 46436 | K27: Monthly | L27: 1400 | M27: 500 | O27: 600310101 | P27: AE34 7116 8008 1475 7554 996 | Q27: Active | R27: =IF(I27="","",I27-TODAY()) -> 109 | S27: =IF(J27="","",J27-TODAY()) -> 109 | T27: =IF(A27="","",IF(OR(AND(R27<>"",R27<0),AND(S27<>"",S27<0)),"EXPIRED",IF(OR(AND(R27<>"",R27<=Settings!$B$15),AND(S27<>"",S27<=Settings!$B$15)),"EXPIRING SOON","OK"))) -> OK | U27: =IF(AND(C27="Own",Q27="Active"),COUNTIFS($C$5:C27,"Own",$Q$5:Q27,"Active"),"") -> 23 | V27: =IF(C27<>"Own","",IF(K27="Hourly",N27,(L27+M27)/(Settings!$B$11*Settings!$B$12))) -> 9.1346154
A28: W0024 | B28: Tariq Gurung | C28: Own | E28: Electrician | F28: Bangladesh | G28: P6765705 | H28: 51907205997105 | I28: 46352 | J28: 46357 | K28: Hourly | N28: 11 | O28: 600310101 | P28: AE93 5262 7655 4910 5928 594 | Q28: Active | R28: =IF(I28="","",I28-TODAY()) -> 25 | S28: =IF(J28="","",J28-TODAY()) -> 30 | T28: =IF(A28="","",IF(OR(AND(R28<>"",R28<0),AND(S28<>"",S28<0)),"EXPIRED",IF(OR(AND(R28<>"",R28<=Settings!$B$15),AND(S28<>"",S28<=Settings!$B$15)),"EXPIRING SOON","OK"))) -> EXPIRING SOON | U28: =IF(AND(C28="Own",Q28="Active"),COUNTIFS($C$5:C28,"Own",$Q$5:Q28,"Active"),"") -> 24 | V28: =IF(C28<>"Own","",IF(K28="Hourly",N28,(L28+M28)/(Settings!$B$11*Settings!$B$12))) -> 11
A29: W0025 | B29: Tariq Santos | C29: Own | E29: Plumber | F29: Bangladesh | G29: P3342033 | H29: 37077826553945 | I29: 46612 | J29: 46617 | K29: Monthly | L29: 2000 | M29: 400 | O29: 803320101 | P29: AE21 3862 6602 2492 6231 344 | Q29: Active | R29: =IF(I29="","",I29-TODAY()) -> 285 | S29: =IF(J29="","",J29-TODAY()) -> 290 | T29: =IF(A29="","",IF(OR(AND(R29<>"",R29<0),AND(S29<>"",S29<0)),"EXPIRED",IF(OR(AND(R29<>"",R29<=Settings!$B$15),AND(S29<>"",S29<=Settings!$B$15)),"EXPIRING SOON","OK"))) -> OK | U29: =IF(AND(C29="Own",Q29="Active"),COUNTIFS($C$5:C29,"Own",$Q$5:Q29,"Active"),"") -> 25 | V29: =IF(C29<>"Own","",IF(K29="Hourly",N29,(L29+M29)/(Settings!$B$11*Settings!$B$12))) -> 11.538462
A30: W0026 | B30: Bikash Thapa | C30: Own | E30: Steel Fixer | F30: Philippines | G30: P7042234 | H30: 84481189948222 | I30: 46779 | J30: 46784 | K30: Monthly | L30: 2500 | M30: 400 | O30: 402320106 | P30: AE37 2517 5440 5070 7300 509 | Q30: Active | R30: =IF(I30="","",I30-TODAY()) -> 452 | S30: =IF(J30="","",J30-TODAY()) -> 457 | T30: =IF(A30="","",IF(OR(AND(R30<>"",R30<0),AND(S30<>"",S30<0)),"EXPIRED",IF(OR(AND(R30<>"",R30<=Settings!$B$15),AND(S30<>"",S30<=Settings!$B$15)),"EXPIRING SOON","OK"))) -> OK | U30: =IF(AND(C30="Own",Q30="Active"),COUNTIFS($C$5:C30,"Own",$Q$5:Q30,"Active"),"") -> 26 | V30: =IF(C30<>"Own","",IF(K30="Hourly",N30,(L30+M30)/(Settings!$B$11*Settings!$B$12))) -> 13.942308
A31: W0027 | B31: Ronel Ahmed | C31: Own | E31: Plumber | F31: Bangladesh | G31: P8532138 | H31: 41495463530590 | I31: 46787 | J31: 46827 | K31: Monthly | L31: 2000 | M31: 300 | O31: 803320101 | P31: AE29 9558 2784 8492 2392 664 | Q31: Active | R31: =IF(I31="","",I31-TODAY()) -> 460 | S31: =IF(J31="","",J31-TODAY()) -> 500 | T31: =IF(A31="","",IF(OR(AND(R31<>"",R31<0),AND(S31<>"",S31<0)),"EXPIRED",IF(OR(AND(R31<>"",R31<=Settings!$B$15),AND(S31<>"",S31<=Settings!$B$15)),"EXPIRING SOON","OK"))) -> OK | U31: =IF(AND(C31="Own",Q31="Active"),COUNTIFS($C$5:C31,"Own",$Q$5:Q31,"Active"),"") -> 27 | V31: =IF(C31<>"Own","",IF(K31="Hourly",N31,(L31+M31)/(Settings!$B$11*Settings!$B$12))) -> 11.057692
A32: W0028 | B32: Anwar Kumar | C32: Own | E32: Mason | F32: Philippines | G32: P4216221 | H32: 46715047245502 | I32: 46625 | J32: 46665 | K32: Monthly | L32: 2000 | M32: 400 | O32: 803320101 | P32: AE86 1018 1171 9806 5940 571 | Q32: Active | R32: =IF(I32="","",I32-TODAY()) -> 298 | S32: =IF(J32="","",J32-TODAY()) -> 338 | T32: =IF(A32="","",IF(OR(AND(R32<>"",R32<0),AND(S32<>"",S32<0)),"EXPIRED",IF(OR(AND(R32<>"",R32<=Settings!$B$15),AND(S32<>"",S32<=Settings!$B$15)),"EXPIRING SOON","OK"))) -> OK | U32: =IF(AND(C32="Own",Q32="Active"),COUNTIFS($C$5:C32,"Own",$Q$5:Q32,"Active"),"") -> 28 | V32: =IF(C32<>"Own","",IF(K32="Hourly",N32,(L32+M32)/(Settings!$B$11*Settings!$B$12))) -> 11.538462
A33: W0029 | B33: Joseph Hossain | C33: Own | E33: Carpenter | F33: Bangladesh | G33: P2360499 | H33: 42063035771278 | I33: 46947 | J33: 46987 | K33: Monthly | L33: 1500 | M33: 300 | O33: 402320106 | P33: AE64 7065 4715 9076 1558 812 | Q33: Active | R33: =IF(I33="","",I33-TODAY()) -> 620 | S33: =IF(J33="","",J33-TODAY()) -> 660 | T33: =IF(A33="","",IF(OR(AND(R33<>"",R33<0),AND(S33<>"",S33<0)),"EXPIRED",IF(OR(AND(R33<>"",R33<=Settings!$B$15),AND(S33<>"",S33<=Settings!$B$15)),"EXPIRING SOON","OK"))) -> OK | U33: =IF(AND(C33="Own",Q33="Active"),COUNTIFS($C$5:C33,"Own",$Q$5:Q33,"Active"),"") -> 29 | V33: =IF(C33<>"Own","",IF(K33="Hourly",N33,(L33+M33)/(Settings!$B$11*Settings!$B$12))) -> 8.6538462
A34: W0030 | B34: Asif Reyes | C34: Own | E34: Cleaner | F34: Pakistan | G34: P8803319 | H34: 47298447088097 | I34: 46894 | J34: 46894 | K34: Monthly | L34: 1800 | M34: 300 | O34: 600310101 | P34: AE23 9122 4068 4658 8947 527 | Q34: Active | R34: =IF(I34="","",I34-TODAY()) -> 567 | S34: =IF(J34="","",J34-TODAY()) -> 567 | T34: =IF(A34="","",IF(OR(AND(R34<>"",R34<0),AND(S34<>"",S34<0)),"EXPIRED",IF(OR(AND(R34<>"",R34<=Settings!$B$15),AND(S34<>"",S34<=Settings!$B$15)),"EXPIRING SOON","OK"))) -> OK | U34: =IF(AND(C34="Own",Q34="Active"),COUNTIFS($C$5:C34,"Own",$Q$5:Q34,"Active"),"") -> 30 | V34: =IF(C34<>"Own","",IF(K34="Hourly",N34,(L34+M34)/(Settings!$B$11*Settings!$B$12))) -> 10.096154
A35: W0031 | B35: Marlon Kumar | C35: Own | E35: Mason | F35: Nepal | G35: P2899274 | H35: 21171199327519 | I35: 46442 | J35: 46447 | K35: Monthly | L35: 2000 | M35: 500 | O35: 803320101 | P35: AE52 4124 4039 9598 8661 132 | Q35: Active | R35: =IF(I35="","",I35-TODAY()) -> 115 | S35: =IF(J35="","",J35-TODAY()) -> 120 | T35: =IF(A35="","",IF(OR(AND(R35<>"",R35<0),AND(S35<>"",S35<0)),"EXPIRED",IF(OR(AND(R35<>"",R35<=Settings!$B$15),AND(S35<>"",S35<=Settings!$B$15)),"EXPIRING SOON","OK"))) -> OK | U35: =IF(AND(C35="Own",Q35="Active"),COUNTIFS($C$5:C35,"Own",$Q$5:Q35,"Active"),"") -> 31 | V35: =IF(C35<>"Own","",IF(K35="Hourly",N35,(L35+M35)/(Settings!$B$11*Settings!$B$12))) -> 12.019231
A36: W0032 | B36: Sanjay Santos | C36: Own | E36: Steel Fixer | F36: Philippines | G36: P4479635 | H36: 60192620465646 | I36: 46817 | J36: 46817 | K36: Hourly | N36: 11 | O36: 600310101 | P36: AE65 2437 1807 8757 4206 481 | Q36: Active | R36: =IF(I36="","",I36-TODAY()) -> 490 | S36: =IF(J36="","",J36-TODAY()) -> 490 | T36: =IF(A36="","",IF(OR(AND(R36<>"",R36<0),AND(S36<>"",S36<0)),"EXPIRED",IF(OR(AND(R36<>"",R36<=Settings!$B$15),AND(S36<>"",S36<=Settings!$B$15)),"EXPIRING SOON","OK"))) -> OK | U36: =IF(AND(C36="Own",Q36="Active"),COUNTIFS($C$5:C36,"Own",$Q$5:Q36,"Active"),"") -> 32 | V36: =IF(C36<>"Own","",IF(K36="Hourly",N36,(L36+M36)/(Settings!$B$11*Settings!$B$12))) -> 11
A37: W0033 | B37: Tariq Varghese | C37: Own | E37: Steel Fixer | F37: India | G37: P2040252 | H37: 37433059994682 | I37: 46317 | J37: 46322 | K37: Monthly | L37: 2000 | M37: 400 | O37: 402320106 | P37: AE18 6555 6946 5461 6488 731 | Q37: Active | R37: =IF(I37="","",I37-TODAY()) -> -10 | S37: =IF(J37="","",J37-TODAY()) -> -5 | T37: =IF(A37="","",IF(OR(AND(R37<>"",R37<0),AND(S37<>"",S37<0)),"EXPIRED",IF(OR(AND(R37<>"",R37<=Settings!$B$15),AND(S37<>"",S37<=Settings!$B$15)),"EXPIRING SOON","OK"))) -> EXPIRED | U37: =IF(AND(C37="Own",Q37="Active"),COUNTIFS($C$5:C37,"Own",$Q$5:Q37,"Active"),"") -> 33 | V37: =IF(C37<>"Own","",IF(K37="Hourly",N37,(L37+M37)/(Settings!$B$11*Settings!$B$12))) -> 11.538462
